<?xml version="1.0"?>

<robot xmlns:sensor="http://playerstage.sourceforge.net/gazebo/xmlschema/#sensor"
xmlns:controller="http://playerstage.sourceforge.net/gazebo/xmlschema/#controller"
xmlns:interface="http://playerstage.sourceforge.net/gazebo/xmlschema/#interface"
  xmlns:xacro="http://ros.org/wiki/xacro"
  >  
  
    <property name="M_PI" value="3.1415926535897931" />
  
    <xacro:macro name="generic_camera" params="name parent *origin ros_topic cam_info_topic update_rate res_x res_y image_format hfov">
      <joint name="${name}_roll" type="revolute">
        <insert_block name="origin" />
        <parent link="${parent}"/>
        <child link="${name}_interm_link"/>
	<axis xyz="1 0 0" />
	<limit effort="0.1" lower="${-M_PI/4}" upper="${M_PI/4}" velocity="0.2" />
      </joint>

      <link name="${name}_interm_link" >
	<inertial>
	  <mass value="0.010" />
	  <origin xyz="0 0 0" rpy="0 0 0" />
	  <!-- assume a sphere of r = 1cm - 2/5 * mr^2 = 4e-7 -->
          <inertia ixx="4e-7" ixy="0" ixz="0" iyy="4e-7" iyz="0" izz="4e-7" />
	</inertial>
      </link>

      <joint name="${name}_pitch" type="revolute">
        <insert_block name="origin" />
        <parent link="${name}_interm_link"/>
        <child link="${name}_link"/>
	<axis xyz="0 1 0" />
	<limit effort="0.1" lower="${-M_PI/4}" upper="${M_PI/4}" velocity="0.2" />
      </joint>

      <link name="${name}_link">
        <inertial>
          <mass value="0.172" />
          <origin xyz="0 0 0" rpy="0 0 0" />
	  <!-- x = depth
	       y = width
	       z = height
	  solid cube = 1/12 * m( h^2 + w^2 ) - 0.000077
	                    1/12 * m( h^2 + d^2 ) - 0.000037
			    1/12 * m( w^2 + d^2 ) - 0.000065 -->
          <inertia ixx="0.000077" ixy="0" ixz="0" iyy="0.00037" iyz="0" izz="0.000065" />
        </inertial>
        <visual>
          <origin xyz="0 0 0" rpy="0 0 0" />
          <geometry>
            <box size="0.030 0.060 0.041" />
          </geometry>
	  <material name="Grey">
	    <color rgba="0.5 0.5 0.5 1"/>
	  </material>
        </visual>
        <collision>
          <origin xyz="0 0 0" rpy="0 0 0" />
          <geometry>
            <box size="0.030 0.060 0.041" />
          </geometry>
        </collision>
      </link>
      
      
    <joint name="${name}_optical_joint" type="fixed">
      <origin xyz="0 0 0" rpy="${-M_PI/2} 0.0 ${-M_PI/2}" />
      <parent link="${name}_link" />
      <child link="${name}_optical_frame"/>
    </joint>
    
    <link name="${name}_optical_frame">
      <inertial>
        <mass value="0.01" />
        <origin xyz="0 0 0" />
        <inertia ixx="0.001"  ixy="0.0"  ixz="0.0"
                 iyy="0.001"  iyz="0.0"
                 izz="0.001" />
      </inertial>
      <visual>
        <origin xyz="0 0 0" rpy="0 0 0"/>
        <geometry>
          <box size="0.001 0.001 0.001" />
        </geometry>
      </visual>
      <collision>
        <origin xyz="0 0 0" rpy="0 0 0"/>
        <geometry>
          <box size="0.001 0.001 0.001" />
        </geometry>
      </collision>
    </link>
      
    <gazebo reference="${name}_link">
      <sensor:camera name="${name}_camera_sensor">
        <imageSize>${res_x} ${res_y}</imageSize>
        <imageFormat>${image_format}</imageFormat>
        <hfov>${hfov}</hfov>
        <nearClip>0.01</nearClip>
        <farClip>100</farClip>
        <updateRate>${update_rate}</updateRate>
        <controller:gazebo_ros_depth_camera name="${name}_camera_controller" plugin="libgazebo_ros_depth_camera.so">
	  <cameraName>${name}</cameraName>
          <alwaysOn>true</alwaysOn>
          <updateRate>${update_rate}</updateRate>
          <imageTopicName>${ros_topic}</imageTopicName>
          <cameraInfoTopicName>${cam_info_topic}</cameraInfoTopicName>
          <frameName>${name}_optical_frame</frameName>
          <interface:camera name="${name}_camera_iface" />
        </controller:gazebo_ros_depth_camera>
      </sensor:camera>
      <turnGravityOff>true</turnGravityOff>
      <material>white</material>
    </gazebo>
    </xacro:macro>
  </robot>
  
